<?xml version="1.0"?>
<!--
Copyright (c) 2016, Renan Maffei, Phi Robotics Reseach Group, INF - UFRGS
Copyright (c) 2013, Goncalo Cabrita, ISR University of Coimbra
All rights reserved.

Redistribution and use in source and binary forms, with or without
modification, are permitted provided that the following conditions are met:
    * Redistributions of source code must retain the above copyright
      notice, this list of conditions and the following disclaimer.
    * Redistributions in binary form must reproduce the above copyright
      notice, this list of conditions and the following disclaimer in the
      documentation and/or other materials provided with the distribution.
    * Neither the name of Clearpath Robotics nor the
      names of its contributors may be used to endorse or promote products
      derived from this software without specific prior written permission.

THIS SOFTWARE IS PROVIDED BY THE COPYRIGHT HOLDERS AND CONTRIBUTORS "AS IS" AND
ANY EXPRESS OR IMPLIED WARRANTIES, INCLUDING, BUT NOT LIMITED TO, THE IMPLIED
WARRANTIES OF MERCHANTABILITY AND FITNESS FOR A PARTICULAR PURPOSE ARE
DISCLAIMED. IN NO EVENT SHALL THE COPYRIGHT HOLDERS BE LIABLE FOR ANY
DIRECT, INDIRECT, INCIDENTAL, SPECIAL, EXEMPLARY, OR CONSEQUENTIAL DAMAGES
(INCLUDING, BUT NOT LIMITED TO, PROCUREMENT OF SUBSTITUTE GOODS OR SERVICES;
LOSS OF USE, DATA, OR PROFITS; OR BUSINESS INTERRUPTION) HOWEVER CAUSED AND
ON ANY THEORY OF LIABILITY, WHETHER IN CONTRACT, STRICT LIABILITY, OR TORT
(INCLUDING NEGLIGENCE OR OTHERWISE) ARISING IN ANY WAY OUT OF THE USE OF THIS
SOFTWARE, EVEN IF ADVISED OF THE POSSIBILITY OF SUCH DAMAGE.
-->

<robot xmlns:sensor="http://playerstage.sourceforge.net/gazebo/xmlschema/#sensor"
    xmlns:controller="http://playerstage.sourceforge.net/gazebo/xmlschema/#controller"
    xmlns:interface="http://playerstage.sourceforge.net/gazebo/xmlschema/#interface"
    xmlns:xacro="http://ros.org/wiki/xacro" name="ptu_d46">

    <!-- PTU-D46 Pan and Tilt Module -->

    <xacro:macro name="ptu_d46" params="parent x y z rx ry rz"> 
        <link name="ptu_d46_base_link">
            <inertial>
                <origin xyz="0.03452 0.022448 0.0215" rpy="0 0 0" />
                <mass value="0.1332" />
                <inertia ixx="4.2943E-05" ixy="5.8886E-08" ixz="1.5845E-22" iyy="7.3506E-05" iyz="-2.7369E-21" izz="7.532E-05" />
            </inertial>
            <visual>
                <origin xyz="0 0 0" rpy="0 0 0" />
                <geometry>
                    <mesh filename="package://loop_exploration/description/sensors_meshes/ptu_d46_base_link.stl" />
                </geometry>
                <material name="DarkGray" />
            </visual>
            <collision>
                <origin xyz="0 0 0" rpy="0 0 0" />
                <geometry>
                    <mesh filename="package://loop_exploration/description/sensors_meshes/ptu_d46_base_link.stl" />
                </geometry>
            </collision>
        </link>
        <gazebo reference="ptu_d46_base_link">
            <material>Gazebo/Yellow</material>
            <turnGravityOff>false</turnGravityOff>
        </gazebo>

        <joint name="ptu_d46_joint" type="fixed">
            <parent link="${parent}"/>
            <child link="ptu_d46_base_link"/>
            <origin xyz="${x} ${y} ${z}" rpy="${rx} ${ry} ${rz}" /> 
        </joint>

        <link name="ptu_d46_pan_link">
            <inertial>
                <origin xyz="-3.4694E-18 -3.4694E-18 0.033962" rpy="0 0 0" />
                <mass value="0.11614" />
                <inertia ixx="5.859E-05" ixy="-5.0822E-21" ixz="1.9911E-23" iyy="5.7898E-05" iyz="-1.6E-21" izz="3.4684E-05" />
            </inertial>
            <visual>
                <origin xyz="0 0 0" rpy="0 0 0" />
                <geometry>
                    <mesh filename="package://loop_exploration/description/sensors_meshes/ptu_d46_pan_link.stl" />
                </geometry>
                <material name="DarkGray" />
            </visual>
            <collision>
                <origin xyz="0 0 0" rpy="0 0 0" />
                <geometry>
                    <mesh filename="package://loop_exploration/description/sensors_meshes/ptu_d46_pan_link.stl" />
                </geometry>
            </collision>
        </link>
        <gazebo reference="ptu_d46_pan_link">
            <material>Gazebo/FlatBlack</material>
            <turnGravityOff>false</turnGravityOff>
        </gazebo>

        <joint name="ptu_d46_pan_joint" type="revolute">
            <origin xyz="0.026 -0.0215 0.044" rpy="-6.123E-17 0 0" />
            <parent link="ptu_d46_base_link" />
            <child link="ptu_d46_pan_link" />
            <axis xyz="0 0 -1" />
            <limit effort="6.0" lower="-0.5" upper="0.5" velocity="0.5" />
            <dynamics damping="0.008" friction="0.6" />
        </joint>

        <link name="ptu_d46_tilt_link">
            <inertial>
                <origin xyz="4.5103E-17 0.019688 0" rpy="0 0 0" />
                <mass value="0.036018" />
                <inertia ixx="1.0844E-05" ixy="-7.4115E-22" ixz="8.6821E-21" iyy="2.2806E-05" iyz="-2.5411E-21" izz="2.9855E-05" />
            </inertial>
            <visual>
                <origin xyz="0 0 0" rpy="0 0 0" />
                <geometry>
                    <mesh filename="package://loop_exploration/description/sensors_meshes/ptu_d46_tilt_link.stl" />
                </geometry>
                <material name="DarkGray" />
            </visual>
            <collision>
                <origin xyz="0 0 0" rpy="0 0 0" />
                <geometry>
                    <mesh filename="package://loop_exploration/description/sensors_meshes/ptu_d46_tilt_link.stl" />
                </geometry>
            </collision>
        </link>
        <gazebo reference="ptu_d46_tilt_link">
            <material>Gazebo/FlatBlack</material>
            <turnGravityOff>false</turnGravityOff>
        </gazebo>

        <joint name="ptu_d46_tilt_joint" type="revolute">
            <origin xyz="0 0 0.0455" rpy="1.3 0 0" />
            <parent link="ptu_d46_pan_link" />
            <child link="ptu_d46_tilt_link" />
            <axis xyz="-1 0 0" />
            <limit effort="6.0" lower="-0.5" upper="0.5" velocity="0.5" />
            <dynamics damping="0.008" friction="0.6" />
        </joint>

        <transmission name="pan">
            <type>transmission_interface/SimpleTransmission</type>
            <joint name="ptu_d46_pan_joint">
                <hardwareInterface>EffortJointInterface</hardwareInterface>
            </joint>
            <actuator name="pan_motor">
                <hardwareInterface>EffortJointInterface</hardwareInterface>
                <mechanicalReduction>1</mechanicalReduction>
            </actuator>
        </transmission>

        <transmission name="tilt">
            <type>transmission_interface/SimpleTransmission</type>
            <joint name="ptu_d46_tilt_joint">
                <hardwareInterface>EffortJointInterface</hardwareInterface>
            </joint>
            <actuator name="tilt_motor">
                <hardwareInterface>EffortJointInterface</hardwareInterface>
                <mechanicalReduction>1</mechanicalReduction>
            </actuator>
        </transmission>

        <!--<gazebo>
        <plugin name="gazebo_ros_control" filename="libgazebo_ros_control.so">
            <robotNamespace>/ptu_d46</robotNamespace>
        </plugin>
        </gazebo>-->

    </xacro:macro>
</robot>
